import {
  ConflictException,
  InternalServerErrorException,
} from '@nestjs/common';
import { EntityRepository, Repository } from 'typeorm';
import { AuthCredentialsDto } from './dto/auth-credentials.dto';
import { User } from './user.entity';
import * as bcrypt from 'bcrypt';
import { UserRolls } from './user-roll.enum';

@EntityRepository(User)
export class UsersRepository extends Repository<User> {
  async createUser(authCredentialsDto: AuthCredentialsDto): Promise<void> {
    const { username, password, roll } = authCredentialsDto;

    const salt = await bcrypt.genSalt();
    const hashedPassword = await bcrypt.hash(password, salt);

    const user = this.create({
      username,
      password: hashedPassword,
      roll ,
    });
    console.log(user);
    try {
      await this.save(user);
    } catch (error) {
      if (error.code === '23505') {
        throw new ConflictException('Username already exists');
      } else {
        throw new InternalServerErrorException();
      }
    }
  }
}
